Workbook

Sheet 0_README
A1: DAY 22 — MONETIZATION MODEL
A2: AI Pricing · GTM · Evidence — AI-IN-ACTION Track 1
A4: QUY ƯỚC MÀU — CHỈ ĐIỀN VÀO Ô MÀU VÀNG
A5: Ô VÀNG, chữ xanh dương | B5: Ô bạn phải điền
A6: Ô XÁM, chữ đen | B6: Công thức tự tính — KHÔNG SỬA
A7: Chữ xanh lá | B7: Link sang tab khác
A8: Ô XÁM đậm nhạt | B8: Bảng tham chiếu, chỉ đọc
A10: THỨ TỰ LÀM — 6 TRẠM, 120 PHÚT
A11: Trạm 1 · 15' | B11: Ngân sách khách & định nghĩa Job → điền S1–S2 của tab 1_Cost_Job
A12: Trạm 2 · 20' | B12: Value Metric → tab 3_Value_Metric
A13: Trạm 3 · 30' | B13: Cost/Job, giá sàn & giá trần → tab 1_Cost_Job (S3–S8) rồi 2_Pricing
A14: Trạm 4 · 20' | B14: Kênh phân phối & Affordability Test → tab 4_Channel_Fit
A15: Trạm 5 · 15' | B15: Pain Moment & 90-Day Plan → tab 5_90Day_Plan
A16: Trạm 6 · 20' | B16: Evidence Pack & ráp One-Pager → tab 5_90Day_Plan + file .docx
A18: 3 QUY TẮC KHÔNG ĐƯỢC PHÁ
A19: 1. Chia cho số job HOÀN THÀNH, không phải số job đã thử.
A20: 2. HITL và Retry không được để 0 nếu không có lý do viết ra được.
A21: 3. Mọi con số giá API phải có NGÀY kiểm tra (xem tab 6_Benchmarks).
A23: Giá tham chiếu trong workbook này được chốt ngày 26/08/2026. Nhiều mức giá là KHUYẾN MẠI CÓ HẠN.
A24: Bạn PHẢI tự mở lại trang giá của nhà cung cấp và cập nhật — đây là một phần của bài tập.

Sheet 1_Cost_Job
A1: TAB 1 — COST/JOB CALCULATOR
A2: Trạm 1 (S1–S2) và Trạm 3 (S3–S8). Chỉ điền ô vàng.
A4: S1. ĐỊNH NGHĨA JOB
A5: 1 job của bạn là gì? | B5: Weekly priority plan: every open task ranked once; preserve source deadlines; show unscheduled items and warnings; save and present. | D5: JOB DELIVERED = schema/invariants pass, full task coverage, source deadlines preserved, warnings retained, persisted and presented. Unscheduled tasks can still be delivered, but usefulness is unproven.
A6: Biến thể HITL: A hay B? | B6: A | D6: A policy test hypothesis: four monthly generation credits. One max-2-call transient/API retry is inside a credit; a generation still failing after retry consumes that credit. No extra free generation/refund assumed.
A8: S2. KHỐI LƯỢNG
A9: Số job THỬ / tháng | B9: 4 | C9: job | D9: A generation credit/request, not a provider API call. Four-credit cap per paid seat-month (policy hypothesis).
A10: Containment rate (AI tự làm xong) | B10: 0.85 | D10: ESTIMATE only; no model or customer success measurement. This R is separate from the 8% provider retry probability.
A11: → Số job HOÀN THÀNH / tháng | B11: =B9*B10 -> 3.4 | C11: job | D11: MẪU SỐ của Cost/Job
A12: → Expected failed AI generations / month | B12: =B9-B11 -> 0.6 | C12: job | D12: R failure estimate among generation credits; not vendor escalation. Unscheduled tasks are a quality diagnostic, not the same as failed jobs.
A14: S3. API — LLM
A15: Giá input ($ / 1M token) | B15: 1 | D15: PROPOSED Anthropic Claude Haiku 4.5 API design scenario; not called in this run.
A16: Giá output ($ / 1M token) | B16: 5
A17: Giá cache WRITE ($ / 1M token) | B17: 1.25 | D17: Anthropic 5-phút = 1,25× input
A18: Giá cache READ ($ / 1M token) | B18: 0.1 | D18: ≈ 0,1× input (giảm 90%)
A19: Số lượt (turns) / job | B19: 1 | C19: lượt
A20: Token input CACHE ĐƯỢC / lượt | B20: 0 | C20: token | D20: No caching assumed; all input treated as fresh for conservative low-volume estimate.
A21: Token input FRESH / lượt | B21: 4000 | C21: token | D21: Câu hỏi khách + dữ liệu động
A22: Token output / lượt | B22: 800 | C22: token
A23: → Cache write / job | B23: =B20*B17/1000000 -> 0
A24: → Cache read / job | B24: =(B19-1)*B20*B18/1000000 -> 0
A25: → Input fresh / job | B25: =B19*B21*B15/1000000 -> 0.004
A26: → Output / job | B26: =B19*B22*B16/1000000 -> 0.004
A27: → LLM / job — CÓ prompt caching | B27: =SUM(B23:B26) -> 0.008
A28: → LLM / job — KHÔNG cache | B28: =B19*(B20+B21)*B15/1000000+B26 -> 0.008
A29: → % tiết kiệm nhờ caching | B29: =IF(B28=0,0,1-B27/B28) -> 0 | D29: Đòn bẩy rẻ nhất bạn có
A30: Dùng Batch API? (1 = có, 0 = không) | B30: 0 | D30: Batch giảm 50% — chỉ khi job KHÔNG cần realtime
A31: → LLM / job sau Batch | B31: =B27*(1-B30*0.5) -> 0.008
A33: S4. API — SPEECH (để 0 nếu sản phẩm không có thoại)
A34: Giá STT ($ / phút) | B34: 0 | D34: Deepgram streaming list $0,0077/phút
A35: Số phút audio / job | B35: 0 | C35: phút
A36: Giá TTS ($ / 1M ký tự) | B36: 0 | D36: ElevenLabs Flash $50 · Google Standard $4
A37: Số ký tự TTS / job | B37: 0 | C37: ký tự | D37: ≈ 900 ký tự cho mỗi phút bot nói
A38: → Speech / job | B38: =B34*B35+B36*B37/1000000 -> 0
A40: S5. INFRA
A41: Infra / job ($) | B41: 0.25 | D41: ESTIMATE allocation, not invoice: base $0.25/generation. Illustrative monthly split at 100 seats × 4 credits = $100: compute $24, database $16, storage $8, logs/monitoring $12, egress/export $4, shared idle/platform $36. Instrument actual invoice and events before repricing.
A42: Telephony ($ / phút) | B42: 0
A43: → Infra / job | B43: =B41+B42*B35 -> 0.25
A45: S6. RETRY
A46: Tỷ lệ job phải chạy lại | B46: 0.08 | D46: ESTIMATE 8% transient/API retry probability, max 2 provider calls per generation request. Retry API-token cost only is included in B47; R is separate job success. No retry telemetry.
...

Sheet 2_Pricing
A1: TAB 2 — PRICING & SUBSCRIPTION ECONOMICS
A2: Giá sàn, tham chiếu giá trần, gross margin và điều kiện rủi ro của thuê bao.
A4: A. GIÁ SÀN THEO CHI PHÍ TRỰC TIẾP
A5: Chi phí trực tiếp tháng / thuê bao trả phí (từ 1_Cost_Job) | B5: ='1_Cost_Job'!B62+'1_Cost_Job'!B63 -> 1.09456 | C5: $/seat-month | D5: Direct cost of four generation credits; operating overhead excluded.
A6: Hệ số giá sàn tối thiểu | B6: 3 | C6: × | D6: Minimum subscription = 3× monthly direct COGS/seat; overhead excluded.
A7: Giá sàn thuê bao / sinh viên / tháng | B7: =B5*B6 -> 3.28368 | C7: $/seat-month
A9: B. GIÁ TRẦN THAM CHIẾU — CHƯA CÓ DỮ LIỆU KHÁCH HÀNG
A10: Giá trị sinh viên tiết kiệm mỗi tháng, sau khi đo ($) | B10: 0 | D10: Chưa đo: giữ $0 đến khi có thời gian lập kế hoạch và số lần sửa lịch ở baseline/pilot. Giá tham chiếu không chứng minh WTP.
A11: Số kế hoạch giao thành công kỳ vọng / tháng (ước tính) | B11: ='1_Cost_Job'!B11 -> 3.4 | C11: plans
A12: 10% giá trị đo được — chỉ để phân tích độ nhạy | B12: =B10*0.1 -> 0 | C12: $/seat-month
A13: 25% giá trị đo được — chỉ để phân tích độ nhạy | B13: =B10*0.25 -> 0 | C13: $/seat-month
A14: Giá trị nhân công có thể thay thế mỗi tháng, sau khi đo ($) | B14: 0 | D14: Giá trị nhân công và giá trần chưa đo; tỷ lệ 50%/70% chỉ là tham chiếu, không chứng minh khách sẽ trả.
A15: Giá trần tham chiếu: 50% giá trị nhân công đo được | B15: =IF(B11=0,0,B14*0.5) -> 0 | C15: $/seat-month
A16: Giá trần tham chiếu: 70% giá trị nhân công đo được | B16: =IF(B11=0,0,B14*0.7) -> 0 | C16: $/seat-month
A18: C. GIÁ ĐỀ XUẤT VÀ GROSS MARGIN
A19: ★ Giá thuê bao đề xuất ($ / seat-tháng) | B19: ='4_Channel_Fit'!B5 -> 4.99 | C19: $/seat-month | D19: Giả thuyết thương mại: giá cố định theo seat, không thu theo kế hoạch giao. Bốn lượt tạo/tháng; chính sách chưa được duyệt.
A20: Bội số giá thuê bao / chi phí trực tiếp tháng | B20: =IF(B5=0,0,B19/B5) -> 4.5589095 | C20: ×
A21: → GROSS MARGIN THUÊ BAO | B21: =IF(B19=0,0,1-B5/B19) -> 0.7806493 | C21: %
A22: → Giá đề xuất đạt hệ số giá sàn tối thiểu? | B22: =IF(B20>=B6,"OK — ĐẠT","KHÔNG ĐẠT — quay lại tab 1") -> OK — ĐẠT
A23: Trạng thái gross margin so với mục tiêu 60% | B23: =IF(B21>=0.6,"OK — AN TOÀN (≥60%)",IF(B21>=0.5,"CẢNH BÁO (50–60%)","NGUY HIỂM (<50%)")) -> OK — AN TOÀN (≥60%)
A24: Cảnh báo GM trên 85%: rà soát chi phí chưa ghi nhận | B24: =IF(B21>0.85,"NGHI NGỜ — rà soát chi phí chưa ghi nhận","OK") -> OK
A25: Kiểm tra giá đề xuất so với sàn và trần | B25: =IF(OR(NOT(ISNUMBER(B19)),B19<=0),"THIẾU DỮ LIỆU GIÁ",IF(B19<B7,"XEM LẠI — DƯỚI GIÁ SÀN",IF(MAX(B13,B16)<=0,"CHƯA ĐỦ DỮ LIỆU XÁC ĐỊNH GIÁ TRẦN",IF(B19<=MAX(B13,B16),"OK — TRONG VÙNG GIÁ","XEM LẠI — VƯỢT GIÁ TRẦN")))) -> CHƯA ĐỦ DỮ LIỆU XÁC ĐỊNH GIÁ TRẦN
A27: FIXED-SUBSCRIPTION ECONOMICS — NOT OUTCOME BILLING
A28: A policy test hypothesis: four generation credits/month. One bounded technical retry is inside a credit; failed generations consume credit. Not approved launch terms.
A29: Monthly direct COGS / seat (4 credits) | B29: ='1_Cost_Job'!B62+'1_Cost_Job'!B63 -> 1.09456
A30: Fixed monthly subscription price / seat | B30: ='4_Channel_Fit'!B5 -> 4.99
A31: Generation credits per paid seat | B31: ='1_Cost_Job'!B9 -> 4
A32: Expected delivered plans at assumed R | B32: ='1_Cost_Job'!B11 -> 3.4
A33: Expected failed generations (not provider retries) | B33: ='1_Cost_Job'!B12 -> 0.6
A34: R không đổi GM của thuê bao cố định; điều kiện lỗ trực tiếp | B34: ="At current inputs, infrastructure above $"&TEXT(B53,"0.00000")&"/credit lowers GM below 60%; at $"&TEXT(B52,"0.00")&"/credit, stress GM is "&TEXT(D52,"0.00%")&". Zero-direct-GM infrastructure threshold is $"&TEXT(B59,"0.00000")&"/credit with other costs fixed. Total direct COGS break-even is $"&TEXT(B58,"0.00000")&"/credit. GM below 60% is not net loss." -> At current inputs, infrastructure above $0.47536/credit lowers GM below 60%; at $0.50/credit, stress GM is 58.02%. Zero-direct-GM infrastructure threshold is $1.22386/credit with other costs fixed. Total direct COGS break-even is $1.24750/credit. GM below 60% is not net loss. | D34: Break variables: usage/cost per credit, refunds/credits, and retention. Technical retry rate is separate from model completion rate.
A35: → Seat GM vs 60% target | B35: =IF(B21>=0.6,"PASS — under current cost assumptions","FAIL — price/usage/cost needs revision") -> PASS — under current cost assumptions
A37: ĐỘ NHẠY — doanh thu/chi phí thuê bao cố định; số giao và tỷ lệ chẩn đoán đổi theo R
A38: Tỷ lệ hoàn tất R | B38: Kế hoạch giao / seat | C38: Chi phí trực tiếp / seat-tháng | D38: Chi phí / kế hoạch giao | E38: Giá thuê bao / kế hoạch (tỷ lệ chẩn đoán; không phải khoản thu) | F38: GM thuê bao cố định | G38: Lượt tạo lỗi / seat | H38: Xác suất ≥1 lỗi (giả định độc lập)
A39: 0.5 | B39: ='1_Cost_Job'!$B$9*A39 -> 2 | C39: =$B$29 -> 1.09456 | D39: =IF(B39=0,0,C39/B39) -> 0.54728 | E39: =IF(B39=0,0,$B$30/B39) -> 2.495 | F39: =IF($B$30=0,0,1-$B$29/$B$30) -> 0.7806493 | G39: ='1_Cost_Job'!$B$9-B39 -> 2 | H39: =1-A39^'1_Cost_Job'!$B$9 -> 0.9375
A40: 0.6 | B40: ='1_Cost_Job'!$B$9*A40 -> 2.4 | C40: =$B$29 -> 1.09456 | D40: =IF(B40=0,0,C40/B40) -> 0.45606667 | E40: =IF(B40=0,0,$B$30/B40) -> 2.0791667 | F40: =IF($B$30=0,0,1-$B$29/$B$30) -> 0.7806493 | G40: ='1_Cost_Job'!$B$9-B40 -> 1.6 | H40: =1-A40^'1_Cost_Job'!$B$9 -> 0.8704
A41: 0.7 | B41: ='1_Cost_Job'!$B$9*A41 -> 2.8 | C41: =$B$29 -> 1.09456 | D41: =IF(B41=0,0,C41/B41) -> 0.39091429 | E41: =IF(B41=0,0,$B$30/B41) -> 1.7821429 | F41: =IF($B$30=0,0,1-$B$29/$B$30) -> 0.7806493 | G41: ='1_Cost_Job'!$B$9-B41 -> 1.2 | H41: =1-A41^'1_Cost_Job'!$B$9 -> 0.7599
A42: 0.8 | B42: ='1_Cost_Job'!$B$9*A42 -> 3.2 | C42: =$B$29 -> 1.09456 | D42: =IF(B42=0,0,C42/B42) -> 0.34205 | E42: =IF(B42=0,0,$B$30/B42) -> 1.559375 | F42: =IF($B$30=0,0,1-$B$29/$B$30) -> 0.7806493 | G42: ='1_Cost_Job'!$B$9-B42 -> 0.8 | H42: =1-A42^'1_Cost_Job'!$B$9 -> 0.5904
A43: 0.85 | B43: ='1_Cost_Job'!$B$9*A43 -> 3.4 | C43: =$B$29 -> 1.09456 | D43: =IF(B43=0,0,C43/B43) -> 0.32192941 | E43: =IF(B43=0,0,$B$30/B43) -> 1.4676471 | F43: =IF($B$30=0,0,1-$B$29/$B$30) -> 0.7806493 | G43: ='1_Cost_Job'!$B$9-B43 -> 0.6 | H43: =1-A43^'1_Cost_Job'!$B$9 -> 0.47799375
A44: 0.9 | B44: ='1_Cost_Job'!$B$9*A44 -> 3.6 | C44: =$B$29 -> 1.09456 | D44: =IF(B44=0,0,C44/B44) -> 0.30404444 | E44: =IF(B44=0,0,$B$30/B44) -> 1.3861111 | F44: =IF($B$30=0,0,1-$B$29/$B$30) -> 0.7806493 | G44: ='1_Cost_Job'!$B$9-B44 -> 0.4 | H44: =1-A44^'1_Cost_Job'!$B$9 -> 0.3439
A46: R alone does not change fixed-subscription GM. Service delivery and expected failed requests do change.
...

Sheet 3_Value_Metric
A1: TAB 3 — VALUE METRIC SCORECARD
A2: Trạm 2. Chấm 0 / 1 / 2 điểm cho mỗi câu, theo THỰC TẾ HÔM NAY.
A4: A. ATTRIBUTION — bạn đo được kết quả là do AI tạo ra không?
A5: 1. Tôi có log đầy đủ mỗi job AI xử lý, gắn được với kết quả cuối cùng | B5: 0
A6: 2. Tôi có bộ eval đo được tỷ lệ AI làm đúng, có số liệu | B6: 0
A7: 3. Khách hàng đồng ý với cách tôi định nghĩa 'thành công' của một job | B7: 0
A8: 4. Tôi phân biệt được kết quả do AI tạo ra với kết quả do yếu tố khác | B8: 0
A9: 5. Tôi viết được định nghĩa chặt như Intercom: cái gì tính tiền, cái gì không | B9: 1
A10: → ĐIỂM ATTRIBUTION (tối đa 10) | B10: =SUM(B5:B9) -> 1
A12: B. AUTONOMY — AI tự chạy hay cần người?
A13: 1. AI hoàn thành job từ đầu đến cuối, không cần người bấm nút giữa chừng | B13: 0
A14: 2. Job chạy được ngoài giờ hành chính mà không ai trực | B14: 0
A15: 3. Khi AI không chắc, nó tự chuyển tiếp đúng chỗ — không cần người phân loại | B15: 0
A16: 4. Tỷ lệ ca phải có người can thiệp dưới 20% | B16: 0
A17: 5. Người vận hành chỉ kiểm tra mẫu (QA), không xử lý từng ca | B17: 0
A18: → ĐIỂM AUTONOMY (tối đa 10) | B18: =SUM(B13:B17) -> 0
A20: GỢI Ý CỦA MODEL
A21: → Value Metric gợi ý | B21: =IF(AND(B10>=7,B18>=7),"OUTCOME",IF(AND(B10>=7,B18<7),"USAGE",IF(AND(B10<7,B18>=7),"USAGE (an toàn)","SEAT hoặc HYBRID"))) -> SEAT hoặc HYBRID
A22: Ngưỡng 7/10 là quy ước của bài tập, không phải chuẩn ngành — dùng để buộc bạn ra quyết định, không phải để thay bạn quyết định.
A24: BENCHMARK NGƯỢC — 2 sản phẩm thật cùng loại job
A25: RealStudy (official page; adjacent direct planner) | B25: Seat/month | C25: $6.90/month | D25: https://realstudy.app/
A26: StudyEdge AI Pro (official page; student weekly planner) | B26: Seat/month | C26: $9.99/month | D26: https://getstudyedge.com/studyedge-ai
A29: QUYẾT ĐỊNH CUỐI
A30: Value Metric tôi chọn | B30: SEAT / month; 4 plans
A31: Nếu KHÁC gợi ý — lý do thị trường là gì? | B31: No Outcome: no AI logs, model eval, customer acceptance, or attributed student result. Seat is a test hypothesis; WTP unknown.
A32: Decision Note — câu 1: tôi chọn đơn vị nào? | B32: $4.99/seat/month; four generation credits (test policy, not approved).
A33: Decision Note — câu 2: bằng chứng Attribution / Autonomy? | B33: Attribution 1/10 (job definition only); Autonomy 0/10. No LLM or user outcomes measured.
A34: Decision Note — câu 3: mô hình này lỗ trong tình huống nào? | B34: ='2_Pricing'!B34 -> At current inputs, infrastructure above $0.47536/credit lowers GM below 60%; at $0.50/credit, stress GM is 58.02%. Zero-direct-GM infrastructure threshold is $1.22386/credit with other costs fixed. Total direct COGS break-even is $1.24750/credit. GM below 60% is not net loss.

Sheet 4_Channel_Fit
A1: TAB 4 — CHANNEL FIT & AFFORDABILITY TEST
A2: Trạm 4. Chọn ĐÚNG 1 kênh cho 90 ngày đầu — và chứng minh bằng số.
A4: A. NGÂN SÁCH CAC — bạn nuôi nổi kênh nào?
A5: ARPU / tháng ($) | B5: 4.99
A6: Gross Margin (từ tab 2_Pricing) | B6: ='2_Pricing'!B21 -> 0.7806493
A7: Phân khúc (SMB / Mid / Enterprise) | B7: B2C | D7: B2C; 3-month CAC payback is an ESTIMATE gate for low-price PLG, not a Bessemer benchmark.
A8: → CAC payback cho phép (tháng) | B8: =IF(B7="B2C",3,IF(B7="SMB",12,IF(B7="Mid",18,24))) -> 3 | C8: tháng | D8: Bessemer, Scaling to $100M (2024)
A9: ★ NGÂN SÁCH CAC / khách | B9: =B5*B6*B8 -> 11.68632 | D9: ARPU × GM × số tháng payback
A10: → ACV (giá trị hợp đồng / năm) | B10: =B5*12 -> 59.88
A12: B. SALES VIABILITY — một AE phải chốt bao nhiêu deal?
A13: Quota / AE / năm ($) | B13: 500000 | D13: $500k quota retained only as an AE counterfactual, not a UniPilot cost or target.
A14: Số ngày làm việc / năm | B14: 250 | C14: ngày
A15: → Số deal / AE / năm | B15: =IF(B10=0,0,B13/B10) -> 8350.0334
A16: ★ Số deal / AE / NGÀY | B16: =IF(B14=0,0,B15/B14) -> 33.400134 | C16: deal/ngày
A17: → Kết luận Sales-Led | B17: =IF(B16<=1,"KHẢ THI về mặt số học","BẤT KHẢ THI — ACV quá thấp để nuôi sales rep") -> BẤT KHẢ THI — ACV quá thấp để nuôi sales rep
A19: C. ĐỐI CHIẾU CAC THỰC TẾ CỦA MOTION CÓ SALES
A20: Cost per opportunity ($) | B20: 8000 | D20: $8,000/opportunity is an unverified GUIDE reference estimate; do not treat as current UniPilot evidence.
A21: Win rate | B21: 0.25 | D21: 25% assumed win rate solely for counterfactual sales CAC.
A22: → CAC thực tế ước tính / khách | B22: =IF(B21=0,0,B20/B21) -> 32000
A23: ★ Lệch bao nhiêu lần so với ngân sách CAC? | B23: =IF(B9=0,0,B22/B9) -> 2738.2444 | D23: Đây là bằng chứng chọn kênh của bạn
A24: → Kết luận | B24: =IF(B23<=1,"Motion có sales KHẢ THI",IF(B23<=3,"Căng — cần tăng giá hoặc giảm chi phí bán hàng","KHÔNG KHẢ THI — đi PLG hoặc Partner-Led")) -> KHÔNG KHẢ THI — đi PLG hoặc Partner-Led
A26: D. CHẤM ĐIỂM 3 KÊNH (1 = rất kém, 5 = rất tốt)
A27: Tiêu chí | B27: PLG | C27: Sales-Led | D27: Partner-Led
A28: 1. Ngân sách CAC của tôi nuôi nổi kênh này | B28: 1 | C28: 1 | D28: 2 | E28: CAC affordability: current base/stress $28.57/$75 exceed $11.69; only an unmeasured stretch target clears it.
A29: 2. Khách hàng mục tiêu thực sự mua theo cách này | B29: 2 | C29: 1 | D29: 1 | E29: Consumer affordability scored 2/5: no student interviews, price test or income evidence. Re-score after observed checkout/refund data.
A30: 3. Đội hiện tại có năng lực chạy kênh này ngay | B30: 3 | C30: 1 | D30: 1
A31: 4. Tôi tiếp cận được điểm nhúng / partner trong 30 ngày | B31: 2 | C31: 1 | D31: 1
A32: 5. Kênh này đưa tôi đến ĐÚNG Pain Moment | B32: 2 | C32: 1 | D32: 2 | E32: Pain fit scored 2/5: Sunday planning moment is a hypothesis, not an observed repeated behavior. Validate through interviews and diary study.
A33: 6. Tôi đo được hiệu quả trong vòng 90 ngày | B33: 4 | C33: 2 | D33: 2
A34: → TỔNG ĐIỂM | B34: =SUM(B28:B33) -> 14 | C34: =SUM(C28:C33) -> 7 | D34: =SUM(D28:D33) -> 9
A35: → Kênh điểm cao nhất | B35: =IF(AND(B34>=C34,B34>=D34),"PLG",IF(C34>=D34,"Sales-Led","Partner-Led")) -> PLG
A37: E. CHỐT KÊNH
A38: ★ Kênh tôi chọn cho 90 ngày đầu | B38: PLG / self-serve | D38: ĐÚNG 1 kênh. Chọn 2 kênh trở lên bị trừ điểm.
A39: Nếu Partner-Led: TÊN CÔNG TY partner | B39: N/A - no partner selected | D39: 'Các nền tảng trong ngành' = chưa có kênh
A40: Đã nói chuyện với họ chưa? (Rồi / Chưa) | B40: Not applicable
A41: Bạn mang lại giá trị gì cho partner? | B41: PLG: student PWA; manual input + .ics. No LMS connector.
A42: Nếu rơi vào vùng không khả thi — lối thoát nào? | B42: Sales-led fails: $32k CAC vs $11.69 budget (estimates). | D42: Giảm giá để tự phục vụ / tăng giá + service / Partner-Led
A44: PLG CAC SCENARIOS — ALL ASSUMPTIONS, NOT OBSERVED
A45: Metric | B45: Stress | C45: Base | D45: Stretch target | E45: Planning assumptions only; not actual traffic, CAC or conversion
A46: Qualified visits | B46: 500 | C46: 1000 | D46: 50
...

Sheet 5_90Day_Plan
A1: TAB 5 — PAIN MOMENT · 90-DAY PLAN · EVIDENCE PACK
A2: Trạm 5 và Trạm 6.
A4: A. PAIN MOMENT — phải đủ 3 phần
A5: MẤY GIỜ khách đau nhất? | B5: Sunday, 20:00 ICT (PROPOSED pain moment)
A6: Lúc đó họ ĐANG LÀM GÌ? | B6: A student manually reviews deadlines and decides what to start before the coming study week.
A7: Họ đang DÙNG APP / KÊNH NÀO? | B7: Google Calendar and course LMS are the student's context; UniPilot has no verified integration and requires manual entry/paste.
A8: → Điểm nhúng cụ thể của bạn | B8: PROPOSED mobile-first PWA weekly planner with manual task entry/paste and optional .ics download; no OAuth/LMS connector built. | D8: Một bề mặt tích hợp có tên, không phải 'website của chúng tôi'
A10: B. 90-DAY PLAN
B11: THÁNG 1 — Học | C11: THÁNG 2–3 — Đòn bẩy | D11: THÁNG 4+ — Mở rộng
A12: Kênh sử dụng | B12: PLG, self-serve web/PWA (PROPOSED) | C12: PLG, one self-serve student workflow | D12: Consider campus/LMS only after product usage and buyer evidence; not in first 90-day channel
A13: Mục tiêu số khách | B13: 12 interviews; recruit 10 test participants (targets, not actuals) | C13: STRETCH TARGET only: 50 qualified visits → 20 activated → 5 paid (10% visit→paid); not base-case conversion or observed. | D13: Scale only after measured net CAC ≤ $11.69, ≥30% week-4 retention, and refund-adjusted cohorts; target, not observed.
A14: Việc cụ thể 1 | B14: Interview 12 students with overlapping course deadlines; document current workaround and pain frequency. | C14: Run manual task-entry onboarding and .ics usability test; measure activation and weekly plan repeat. | D14: Test one additional academic cohort after retention and unit cost gates pass.
A15: Việc cụ thể 2 | B15: Freeze this offline baseline; prepare an evaluation harness only. Run real-model tests after provider, privacy, budget and safety approval. | C15: Price test $4.99/month against free alternative; report actual conversions only if observed. | D15: Reassess subscription allowance from observed heavy-use distribution.
A16: Việc cụ thể 3 | B16: Recruit opt-in testers; no pilot claim until consent and protocol are approved. | C16: 2-week PLG falsification: 50 tagged visits; record activation, checkout, net paid/refunds, use and retention. Include a small referral/organic test; report zero as zero. | D16: Month 4+ possible campus channel discovery; no partner contacted or assumed.
A17: KPI đo được | B17: Gate: >=8/12 interviews confirm weekly prioritization pain; >=6/10 complete setup unaided. | C17: NO-GO paid scale unless measured net CAC ≤ $11.69 AND week-4 retention ≥30%; base/stress models miss CAC. Stretch 5 paid is a target only; otherwise stop paid spend, revise/test organic referral. | D17: Gate: repeat cohort evidence and paid acquisition payback <=3 months before scale.
A18: Người chịu trách nhiệm | B18: Product lead (proposed; learner to confirm) · target 2026-11-01 | C18: Product + Engineering + GTM leads (proposed; learner to confirm) · target 2026-11-30 | D18: Product/GTM lead (proposed; learner to confirm) · 4-week follow-up through 2026-12-31
A19: Sequence: interview and manual baseline → private, consented test → evaluate retention and net CAC → decide whether to continue. No broad launch assumed.
A21: C. EVIDENCE PACK — 3 tài sản bán hàng
A22: Tài sản | B22: Đã có? (Rồi/Chưa) | C22: Nội dung 1 câu — hoặc việc cần làm | D22: Người phụ trách · Deadline
A23: 1. Eval Results | B23: Offline synthetic baseline exists; no real-model evaluation. | C23: Offline rule baseline: 100/100 synthetic cases passed; only 273/639 task windows assigned. Real-model eval pending. | D23: Product/Engineering lead (proposed; learner to confirm) · model eval only after credential/privacy approval · target 2026-11-15
A24: 2. Risk Checklist | B24: Draft Q&A/risk checklist exists; production controls not verified. | C24: Procurement Q&A and UniPilot risk checklist created; implementation claims marked PLANNED unless cited to code/tests. | D24: Product lead + Security reviewer (proposed; learner to confirm) · controls review · target 2026-11-15
A25: 3. Pilot Report | B25: No real-user pilot has been run. | C25: Synthetic dry-run only; no real-user pilot has been run. | D25: Product/GTM lead (proposed; learner to confirm) · consent/protocol review · target 2026-11-15
A26: Ô nào CHƯA CÓ thì ghi deadline — đừng bỏ trống. Thành thật về khoảng trống được điểm cao hơn bịa nội dung.
A28: D. BÀI TEST NGƯỜI LẠ — nhóm khác đọc One-Pager trong 2 phút
A29: Họ trả lời được: bán gì, cho ai, tính tiền theo đơn vị nào? (Được/Không) | B29: Not tested with human reader
A30: Họ trả lời được: có lãi trên mỗi đơn vị không, số nào chứng minh? (Được/Không) | B30: Not tested with human reader
A31: Họ trả lời được: tiếp cận khách qua đâu, vì sao kênh đó? (Được/Không) | B31: Not tested with human reader
A32: Số câu họ phải hỏi lại (mục tiêu ≤ 3) | B32: N/A - simulated review only

Sheet 6_Benchmarks
A1: TAB 6 — BENCHMARKS (CHỈ ĐỌC)
A2: Advertised competitor facts last checked 2026-10-08; not evidence of UniPilot willingness to pay or outcomes.
A3: NGÀY BẠN KIỂM TRA LẠI GIÁ | B3: 2026-10-08: official RealStudy, StudyEdge AI and Anthropic Haiku 4.5 pricing last checked. Anthropic also lists Haiku 5.5; not substituted without evaluation. Other GUIDE rows not re-verified. | D3: Other GUIDE benchmark rows are reference-only; not rechecked or used to support this positioning.
A5: Nhóm | B5: Mục | C5: Giá | D5: Đơn vị | E5: Nguồn
A6: LLM | B6: Claude Opus 5 — input / output | C6: 5,00 / 25,00 | D6: $ / 1M token | E6: platform.claude.com/docs/en/about-claude/pricing
A7: LLM | B7: Claude Sonnet 5 — input / output | C7: 2,00 / 10,00 | D7: $ / 1M token | E7: platform.claude.com/docs/en/about-claude/pricing
A8: LLM | B8: Claude Haiku 4.5 (legacy scenario) — input / output | C8: $1 / $5 (input/output) | D8: $ / 1M token | E8: https://platform.claude.com/docs/en/models/haiku-4-5/overview
A9: LLM | B9: Claude — cache write 5' / cache read | C9: 1.25x write / 0.10x read (5-min cache) | D9: hệ số | E9: platform.claude.com/docs/en/about-claude/pricing
A10: LLM | B10: ⏳ OpenAI GPT-5.6 Sol — input / output | C10: 4,00 / 20,00 | D10: $ / 1M token | E10: developers.openai.com/api/docs/pricing (KM 21/08–21/11/2026; list 5,00/30,00)
A11: LLM | B11: OpenAI GPT-5.6 Luna — input / output | C11: 0,20 / 1,20 | D11: $ / 1M token | E11: developers.openai.com/api/docs/pricing
A12: LLM | B12: OpenAI — cached input / Batch API | C12: 10% input / −50% | D12: hệ số | E12: developers.openai.com/api/docs/pricing
A13: LLM | B13: Gemini 3.1 Pro — input / output (≤200k) | C13: 2,00 / 12,00 | D13: $ / 1M token | E13: ai.google.dev/gemini-api/docs/pricing
A14: LLM | B14: ⏳ Gemini 3.7 Flash — input / output | C14: 0,75 / 3,75 | D14: $ / 1M token | E14: ai.google.dev/gemini-api/docs/pricing (KM đến 31/12/2026; sau đó 1,50/7,50)
A15: STT | B15: Deepgram Nova-3 — pre-recorded | C15: 0,0043 | D15: $ / phút | E15: deepgram.com/pricing
A16: STT | B16: ⏳ Deepgram Nova-3 — streaming | C16: list 0,0077 · KM 0,0048 | D16: $ / phút | E16: deepgram.com/pricing — đang khuyến mại, kiểm tra lại
... A41: Benchmark | B41: ACV sàn cho inside sales | C41: ≈ 3.000 | D41: $ / năm | E41: Tomasz Tunguz (2016) — có kèm giả định để tính lại
A43: Lưu ý: trang marketing của nhà cung cấp có thể hiển thị giá cũ hơn trang docs. Ưu tiên trang docs / pricing chính thức.
A45: STUDENT PLANNER ALTERNATIVES — PUBLIC CLAIMS; NOT A FEATURE OR OUTCOME AUDIT
A46: Option | B46: Advertised price / allowance | C46: Scheduling / outcomes described | D46: Limit / UniPilot comparison | E46: Primary source; checked 2026-10-08
A47: UniPilot (proposed) | B47: $4.99/mo; four generation credits (policy hypothesis) | C47: Weekly priority plan for manually supplied tasks; flags unscheduled items; optional .ics proposal | D47: No demonstrated auto syllabus import, auto-reschedule, tutor, or calendar/LMS sync. Differentiation unanswered. | E47: Internal proposal; no launch/customer evidence
A48: RealStudy | B48: $6.90/mo after 3-day trial; page advertises unlimited syllabus import/task breakdown | C48: Auto weekly plan, capacity meter, auto-reschedule, .ics export; vendor-described outcomes | D48: Broader published allowance/features than four UniPilot credits; marketing claims, no independent outcome validation. | E48: https://realstudy.app/
A49: StudyEdge AI Pro | B49: $9.99/mo Pro; free 1 course + 5 AI sessions; $14.99 Unlimited | C49: Auto weekly schedule/rebalance; tutor, flashcards, quizzes, grade hub | D49: Broader study suite; vendor-described outcomes, no independent comparison test. | E49: https://getstudyedge.com/studyedge-ai
A50: Manual calendar/LMS | B50: Often included with existing school/account tools; incremental price varies | C50: Can record deadlines and student-blocked time; prioritization, workload fit and time saved unmeasured | D50: Baseline alternative to test. No assumption that UniPilot saves time or improves outcomes. | E50: No single provider/product; establish per participant
A52: Differentiation hypothesis to test: does one consolidated priority plan reduce planning time/corrections vs each student’s current workflow? Measure paired baseline and pilot; no superiority claim.
A53: WTP/value: capture baseline and pilot planning minutes, deadline corrections, unscheduled tasks, actual opt-in checkout, refunds and 4-week retention. No $ value inferred until measured.
